<?xml version="1.0" encoding="utf-8" ?>
<!-- =================================================================================== -->
<!-- |    This document was autogenerated by xacro from /home/rocky/tribot_ws/src/tribot/urdf/singleworld.xacro | -->
<!-- |    EDITING THIS FILE BY HAND IS NOT RECOMMENDED                                 | -->
<!-- =================================================================================== -->
<robot name="single_world">
    <!-- <link name="world" /> -->
    <link name="base_link" />
    <link name="robot_base">

        <inertial>
            <origin rpy="0 0 0" xyz="0 0 0" />
            <mass value="3" />
            <inertia ixx="0.8" ixy="0" ixz="0" iyy="0.8" iyz="0" izz="0.8" />
        </inertial>

        <visual>
            <origin rpy="0 0 0" xyz="0 0 0" />
            <geometry>
                <sphere radius="0.3" />
            </geometry>
            <material name="framemat0">
                <color rgba="1 1 1 1" />
            </material>
        </visual>

        <visual>
            <origin rpy="0 0 0" xyz="0 0 0.3" />
            <geometry>
                <sphere radius="0.1" />
            </geometry>
            <material name="framemat1">
                <color rgba="1 0.2 0.2 1" />
            </material>
        </visual>

        <visual>
            <origin rpy="0 0 0" xyz="0 0.3 0" />
            <geometry>
                <sphere radius="0.1" />
            </geometry>
            <material name="framemat1">
                <color rgba="1 0.2 0.2 1" />
            </material>
        </visual>

        <collision>
            <origin rpy="0 0 0" xyz="0 0 0" />
            <geometry>
                <sphere radius="0.3" />
            </geometry>
        </collision>
    </link>
    <link name="hip_back">

        <inertial>
            <origin rpy="0 0 0" xyz="0 0 0" />
            <mass value="0.3" />
            <inertia ixx="0.05" ixy="0" ixz="0" iyy="0.05" iyz="0" izz="0.05" />
        </inertial>

        <visual>
            <origin rpy="0 0 0" xyz="0 0 0" />
            <geometry>
                <sphere radius="0.05" />
            </geometry>
            <material name="framemat0">
                <color rgba="1 1 1 1" />
            </material>
        </visual>
        <collision>
            <origin rpy="0 0 0" xyz="0 0 0" />
            <geometry>
                <sphere radius="0.05" />
            </geometry>
        </collision>
    </link>
    <link name="leg_back">

        <inertial>
            <origin rpy="0 0 0" xyz="0 0 0.3" />
            <mass value="0.3" />
            <inertia ixx="0.01" ixy="0" ixz="0" iyy="0.01" iyz="0" izz="0.01" />
        </inertial>

        <visual>
            <origin rpy="0 0 0" xyz="0 0 0.3" />
            <geometry>
                <cylinder length="0.6" radius="0.05" />
            </geometry>
            <material name="framemat0">
                <color rgba="1 1 1 1" />
            </material>
        </visual>
        <collision>
            <origin rpy="0 0 0" xyz="0 0 0.3" />
            <geometry>
                <cylinder length="0.6" radius="0.05" />
            </geometry>
        </collision>
        <visual>
            <origin rpy="0 0 0" xyz="0 0 0.6" />
            <geometry>
                <sphere radius="0.05" />
            </geometry>
            <material name="framemat0">
                <color rgba="1 1 1 1" />
            </material>
        </visual>
        <collision>
            <origin rpy="0 0 0" xyz="0 0 0.6" />
            <geometry>
                <sphere radius="0.05" />
            </geometry>
        </collision>
    </link>
    <link name="foot_back">

        <inertial>
            <origin rpy="0 0 0" xyz="0 0 0.3" />
            <mass value="0.3" />
            <inertia ixx="0.01" ixy="0" ixz="0" iyy="0.01" iyz="0" izz="0.01" />
        </inertial>

        <visual>
            <origin rpy="0 0 0" xyz="0 0 0.3" />
            <geometry>
                <cylinder length="0.6" radius="0.05" />
            </geometry>
            <material name="framemat0">
                <color rgba="1 1 1 1" />
            </material>
        </visual>
        <collision>
            <origin rpy="0 0 0" xyz="0 0 0.3" />
            <geometry>
                <cylinder length="0.6" radius="0.05" />
            </geometry>
        </collision>
        <visual>
            <origin rpy="0 0 0" xyz="0 0 0.6" />
            <geometry>
                <sphere radius="0.05" />
            </geometry>
            <material name="framemat0">
                <color rgba="1 1 1 1" />
            </material>
        </visual>
        <collision name ="foot_collision">
            <origin rpy="0 0 0" xyz="0 0 0.6" />
            <geometry>
                <sphere radius="0.05" />
            </geometry>
        </collision>

    </link>
    <joint name="hip_back_joint" type="continuous">
        <parent link="base_link" />
        <child link="hip_back" />
        <origin rpy="0 0 0" xyz="0 0 0" />
        <axis xyz="0 0 1" />
        <!-- <limit effort="10000" lower="-9" upper="9" velocity="100.0" /> -->
    </joint>
    <joint name="leg_back_joint" type="continuous">
        <parent link="hip_back" />
        <child link="leg_back" />
        <origin rpy="0 3.1415 0" xyz="0 0 0" />
        <axis xyz="0 -1 0" />
        <!-- <limit effort="10000" lower="-9" upper="9" velocity="100.0" /> -->
    </joint>
    <joint name="foot_back_joint" type="prismatic">
        <parent link="leg_back" />
        <child link="foot_back" />
        <origin rpy="0 0 0" xyz="0 0 0.6" />
        <axis xyz="0 0 1" />
        <limit effort="10000" lower="-1.0" upper="1.0" velocity="100.0" />
    </joint>
    <joint name="base_joint" type="fixed">
        <parent link="base_link" />
        <child link="robot_base" />
        <origin rpy="0 0 0" xyz="0 0 0" />
        <axis xyz="1 0 0" />
    </joint>

    <transmission name="trans_hip_back_joint">
        <type>transmission_interface/SimpleTransmission</type>
        <joint name="hip_back_joint">
            <hardwareInterface>hardware_interface/EffortJointInterface</hardwareInterface>
        </joint>
        <actuator name="hip_back_joint_motor">
            <hardwareInterface>hardware_interface/EffortJointInterface</hardwareInterface>
            <mechanicalReduction>1</mechanicalReduction>
        </actuator>
    </transmission>
    <transmission name="trans_leg_back_joint">
        <type>transmission_interface/SimpleTransmission</type>
        <joint name="leg_back_joint">
            <hardwareInterface>hardware_interface/EffortJointInterface</hardwareInterface>
        </joint>
        <actuator name="leg_back_joint_motor">
            <hardwareInterface>hardware_interface/EffortJointInterface</hardwareInterface>
            <mechanicalReduction>1</mechanicalReduction>
        </actuator>
    </transmission>
    <transmission name="trans_foot_back_joint">
        <type>transmission_interface/SimpleTransmission</type>
        <joint name="foot_back_joint">
            <hardwareInterface>hardware_interface/EffortJointInterface</hardwareInterface>
        </joint>
        <actuator name="foot_back_joint_motor">
            <hardwareInterface>hardware_interface/EffortJointInterface</hardwareInterface>
            <mechanicalReduction>1</mechanicalReduction>
        </actuator>
    </transmission>
    <gazebo>
        <plugin name="gazebo_ros_control" filename="libgazebo_ros_control.so">
            <robotNamespace>/singlebot</robotNamespace>
        </plugin>
    </gazebo>

    <gazebo reference="robot_base">
        <gravity>true</gravity>
        <sensor name="imu_sensor" type="imu">
            <always_on>true</always_on>
            <update_rate>100</update_rate>
            <visualize>true</visualize>
            <topic>__default_topic__</topic>
            <plugin filename="libgazebo_ros_imu_sensor.so" name="imu_plugin">
                <topicName>imu</topicName>
                <bodyName>robot_base</bodyName>
                <updateRateHZ>1000.0</updateRateHZ>
                <gaussianNoise>0.0</gaussianNoise>
                <xyzOffset>0 0 0</xyzOffset>
                <rpyOffset>0 0 0</rpyOffset>
                <frameName>robot_base</frameName>
                <initialOrientationAsReference>false</initialOrientationAsReference>
            </plugin>
            <pose>0 0 0 0 0 0</pose>
        </sensor>
    </gazebo>


    <!-- Contact Sensor -->
    <gazebo reference="foot_back">
        <sensor name="foot_contact_sensor" type="contact">
            <!-- <always_on>true</always_on> -->
            <!-- <updateRate>100.0</updateRate> -->
            <contact>
                <collision>foot_back_fixed_joint_lump__foot_collision_collision_1</collision>
            </contact>
            <plugin name="foot_back_plugin" filename="libgazebo_ros_bumper.so">
                <alwaysOn>true</alwaysOn>
                <bumperTopicName>/foot_back_contact</bumperTopicName>
                <frameName>world</frameName>
                <updateRate>100.0</updateRate>
            </plugin>
        </sensor>
    </gazebo>


    <gazebo reference="foot_back">
        <collision>
            <surface>
                <friction>
                    <ode>
                        <mu>0.9</mu>
                        <mu2>0.9</mu2>
                    </ode>
                </friction>
            </surface>
        </collision>
    </gazebo>
</robot>