<?xml version="1.0" encoding="utf-8" ?>
<!-- =================================================================================== -->
<!-- |    This document was autogenerated by xacro from /home/rocky/tribot_ws/src/tribot/urdf/singleworld.xacro | -->
<!-- |    EDITING THIS FILE BY HAND IS NOT RECOMMENDED                                 | -->
<!-- =================================================================================== -->
<robot name="single_world">
    <!-- <link name="world"  /> -->
    <link name="base_link" />
    <link name="robot_base">
        
<inertial>
            <origin rpy="0 0 0" xyz="0 0 0" />
            <mass value="3" />
            <inertia ixx="0.1" ixy="0" ixz="0" iyy="0.1" iyz="0" izz="0.1" />
        </inertial>

        <visual>
            <origin rpy="0 0 0" xyz="0 0 0" />
            <geometry>
                <sphere radius="0.3" />
            </geometry>
            <material name="framemat0">
                <color rgba="1 1 1 1" />
            </material>
        </visual>
        <collision>
            <origin rpy="0 0 0" xyz="0 0 0" />
            <geometry>
                <sphere radius="0.3" />
            </geometry>
        </collision>
    </link>
    <link name="hip_back">
        
<inertial>
            <origin rpy="0 0 0" xyz="0 0 0" />
            <mass value="0.3" />
            <inertia ixx="0.1" ixy="0" ixz="0" iyy="0.1" iyz="0" izz="0.1" />
        </inertial>

        <visual>
            <origin rpy="0 0 0" xyz="0 0 0" />
            <geometry>
                <sphere radius="0.05" />
            </geometry>
            <material name="framemat0">
                <color rgba="1 1 1 1" />
            </material>
        </visual>
        <collision>
            <origin rpy="0 0 0" xyz="0 0 0" />
            <geometry>
                <sphere radius="0.05" />
            </geometry>
        </collision>
    </link>
    <link name="leg_back">
        
<inertial>
            <origin rpy="0 0 0" xyz="0 0 0.15" />
            <mass value="0.3" />
            <inertia ixx="0.1" ixy="0" ixz="0" iyy="0.1" iyz="0" izz="0.1" />
        </inertial>

        <visual>
            <origin rpy="0 0 0" xyz="0 0 0.15" />
            <geometry>
                <cylinder length="0.3" radius="0.05" />
            </geometry>
            <material name="framemat0">
                <color rgba="1 1 1 1" />
            </material>
        </visual>
        <collision>
            <origin rpy="0 0 0" xyz="0 0 0.15" />
            <geometry>
                <cylinder length="0.3" radius="0.05" />
            </geometry>
        </collision>
        <visual>
            <origin rpy="0 0 0" xyz="0 0 0.3" />
            <geometry>
                <sphere radius="0.05" />
            </geometry>
            <material name="framemat0">
                <color rgba="1 1 1 1" />
            </material>
        </visual>
        <collision>
            <origin rpy="0 0 0" xyz="0 0 0.3" />
            <geometry>
                <sphere radius="0.05" />
            </geometry>
        </collision>
    </link>
    <link name="foot_back">
        
<inertial>
            <origin rpy="0 0 0" xyz="0 0 0.15" />
            <mass value="0.3" />
            <inertia ixx="0.1" ixy="0" ixz="0" iyy="0.1" iyz="0" izz="0.1" />
        </inertial>

        <visual>
            <origin rpy="0 0 0" xyz="0 0 0.15" />
            <geometry>
                <cylinder length="0.3" radius="0.05" />
            </geometry>
            <material name="framemat0">
                <color rgba="1 1 1 1" />
            </material>
        </visual>
        <collision>
            <origin rpy="0 0 0" xyz="0 0 0.15" />
            <geometry>
                <cylinder length="0.3" radius="0.05" />
            </geometry>
        </collision>
        <visual>
            <origin rpy="0 0 0" xyz="0 0 0.3" />
            <geometry>
                <sphere radius="0.05" />
            </geometry>
            <material name="framemat0">
                <color rgba="1 1 1 1" />
            </material>
        </visual>
        <collision>
            <origin rpy="0 0 0" xyz="0 0 0.3" />
            <geometry>
                <sphere radius="0.05" />
            </geometry>
        </collision>
    </link>
    <joint name="hip_back_joint" type="continuous">
        <parent link="base_link" />
        <child link="hip_back" />
        <origin rpy="0 0 0" xyz="0 0 -0.3" />
        <axis xyz="0 0 1" />
    </joint>
    <joint name="leg_back_joint" type="continuous">
        <parent link="hip_back" />
        <child link="leg_back" />
        <origin rpy="0 3.1415 0" xyz="0 0 0" />
        <axis xyz="0 1 0" />
    </joint>
    <joint name="foot_back_joint" type="prismatic">
        <parent link="leg_back" />
        <child link="foot_back" />
        <origin rpy="0 0 0" xyz="0 0 0.3" />
        <axis xyz="0 0 1" />
        <limit effort="20" lower="-0.1" upper="0.2" velocity="1.0" />
    </joint>
    <joint name="base_joint" type="fixed">
        <parent link="base_link" />
        <child link="robot_base" />
        <origin rpy="0 0 0" xyz="0 0 0" />
        <axis xyz="1 0 0" />
    </joint>
    
<transmission name="trans_hip_back_joint">
        <type>transmission_interface/SimpleTransmission</type>
        <joint name="hip_back_joint">
            <hardwareInterface>EffortJointInterface</hardwareInterface>
        </joint>
        <actuator name="hip_back_joint_motor">
            <hardwareInterface>EffortJointInterface</hardwareInterface>
            <mechanicalReduction>1</mechanicalReduction>
        </actuator>
    </transmission>
    <transmission name="trans_leg_back_joint">
        <type>transmission_interface/SimpleTransmission</type>
        <joint name="leg_back_joint">
            <hardwareInterface>EffortJointInterface</hardwareInterface>
        </joint>
        <actuator name="leg_back_joint_motor">
            <hardwareInterface>EffortJointInterface</hardwareInterface>
            <mechanicalReduction>1</mechanicalReduction>
        </actuator>
    </transmission>
    <transmission name="trans_foot_back_joint">
        <type>transmission_interface/SimpleTransmission</type>
        <joint name="foot_back_joint">
            <hardwareInterface>EffortJointInterface</hardwareInterface>
        </joint>
        <actuator name="foot_back_joint_motor">
            <hardwareInterface>EffortJointInterface</hardwareInterface>
            <mechanicalReduction>1</mechanicalReduction>
        </actuator>
    </transmission>
    <gazebo>
        <plugin name="gazebo_ros_control" filename="libgazebo_ros_control.so">
            <robotNamespace>/singlebot</robotNamespace>
        </plugin>
    </gazebo>
</robot>