<sdf version='1.6'>
  <world name='default'>
    <light name='sun' type='directional'>
      <cast_shadows>1</cast_shadows>
      <pose frame=''>0 0 10 0 -0 0</pose>
      <diffuse>0.8 0.8 0.8 1</diffuse>
      <specular>0.2 0.2 0.2 1</specular>
      <attenuation>
        <range>1000</range>
        <constant>0.9</constant>
        <linear>0.01</linear>
        <quadratic>0.001</quadratic>
      </attenuation>
      <direction>-0.5 0.1 -0.9</direction>
    </light>
    <model name='ground_plane'>
      <static>1</static>
      <link name='link'>
        <collision name='collision'>
          <geometry>
            <plane>
              <normal>0 0 1</normal>
              <size>100 100</size>
            </plane>
          </geometry>
          <surface>
            <contact>
              <collide_bitmask>65535</collide_bitmask>
              <ode/>
            </contact>
            <friction>
              <ode>
                <mu>100</mu>
                <mu2>50</mu2>
              </ode>
              <torsional>
                <ode/>
              </torsional>
            </friction>
            <bounce/>
          </surface>
          <max_contacts>10</max_contacts>
        </collision>
        <visual name='visual'>
          <cast_shadows>0</cast_shadows>
          <geometry>
            <plane>
              <normal>0 0 1</normal>
              <size>100 100</size>
            </plane>
          </geometry>
          <material>
            <script>
              <uri>file://media/materials/scripts/gazebo.material</uri>
              <name>Gazebo/Grey</name>
            </script>
          </material>
        </visual>
        <self_collide>0</self_collide>
        <enable_wind>0</enable_wind>
        <kinematic>0</kinematic>
      </link>
    </model>
    <gravity>0 0 -9.8</gravity>
    <magnetic_field>6e-06 2.3e-05 -4.2e-05</magnetic_field>
    <atmosphere type='adiabatic'/>
    <physics name='default_physics' default='0' type='ode'>
      <max_step_size>0.001</max_step_size>
      <real_time_factor>1</real_time_factor>
      <real_time_update_rate>1000</real_time_update_rate>
    </physics>
    <scene>
      <ambient>0.4 0.4 0.4 1</ambient>
      <background>0.7 0.7 0.7 1</background>
      <shadows>1</shadows>
    </scene>
    <audio>
      <device>default</device>
    </audio>
    <wind/>
    <spherical_coordinates>
      <surface_model>EARTH_WGS84</surface_model>
      <latitude_deg>0</latitude_deg>
      <longitude_deg>0</longitude_deg>
      <elevation>0</elevation>
      <heading_deg>0</heading_deg>
    </spherical_coordinates>
    <model name='singlebot'>
      <link name='base1_link'>
        <pose frame=''>0 0 0 0 -0 0</pose>
        <inertial>
          <pose frame=''>0 0 0 0 -0 0</pose>
          <mass>0.01</mass>
          <inertia>
            <ixx>0.01</ixx>
            <ixy>0</ixy>
            <ixz>0</ixz>
            <iyy>0.01</iyy>
            <iyz>0</iyz>
            <izz>0.01</izz>
          </inertia>
        </inertial>
        <visual name='base1_link_visual'>
          <pose frame=''>0 0 0 0 -0 0</pose>
          <geometry>
            <sphere>
              <radius>0.02</radius>
            </sphere>
          </geometry>
        </visual>
        <self_collide>0</self_collide>
        <enable_wind>0</enable_wind>
        <kinematic>0</kinematic>
      </link>
      <joint name='base_joint' type='prismatic'>
        <child>base1_link</child>
        <parent>world</parent>
        <axis>
          <xyz>0 0 1</xyz>
          <limit>
            <lower>-1000</lower>
            <upper>1000</upper>
            <effort>0</effort>
            <velocity>10</velocity>
          </limit>
          <dynamics>
            <spring_reference>0</spring_reference>
            <spring_stiffness>0</spring_stiffness>
          </dynamics>
          <use_parent_model_frame>1</use_parent_model_frame>
        </axis>
      </joint>
      <link name='base2_link'>
        <pose frame=''>0 0 2 0 -0 0</pose>
        <inertial>
          <pose frame=''>0 0 0 0 -0 0</pose>
          <mass>0.1</mass>
          <inertia>
            <ixx>0.1</ixx>
            <ixy>0</ixy>
            <ixz>0</ixz>
            <iyy>0.1</iyy>
            <iyz>0</iyz>
            <izz>0.1</izz>
          </inertia>
        </inertial>
        <visual name='base2_link_visual'>
          <pose frame=''>0 0 0 0 -0 0</pose>
          <geometry>
            <sphere>
              <radius>0.02</radius>
            </sphere>
          </geometry>
        </visual>
        <self_collide>0</self_collide>
        <enable_wind>0</enable_wind>
        <kinematic>0</kinematic>
      </link>
      <joint name='base2_joint' type='prismatic'>
        <child>base2_link</child>
        <parent>base1_link</parent>
        <axis>
          <xyz>0 1 0</xyz>
          <limit>
            <lower>-1000</lower>
            <upper>1000</upper>
            <effort>0</effort>
            <velocity>10</velocity>
          </limit>
          <dynamics>
            <spring_reference>0</spring_reference>
            <spring_stiffness>0</spring_stiffness>
          </dynamics>
          <use_parent_model_frame>1</use_parent_model_frame>
        </axis>
      </joint>
      <link name='robot_base'>
        <pose frame=''>0 0 2 0 -0 0</pose>
        <inertial>
          <pose frame=''>0 0 0 0 -0 0</pose>
          <mass>3</mass>
          <inertia>
            <ixx>0.8</ixx>
            <ixy>0</ixy>
            <ixz>0</ixz>
            <iyy>0.8</iyy>
            <iyz>0</iyz>
            <izz>0.8</izz>
          </inertia>
        </inertial>
        <collision name='robot_base_collision'>
          <pose frame=''>0 0 0 0 -0 0</pose>
          <geometry>
            <sphere>
              <radius>0.3</radius>
            </sphere>
          </geometry>
          <surface>
            <contact>
              <ode/>
            </contact>
            <friction>
              <ode/>
              <torsional>
                <ode/>
              </torsional>
            </friction>
            <bounce/>
          </surface>
          <max_contacts>10</max_contacts>
        </collision>
        <visual name='robot_base_visual'>
          <pose frame=''>0 0 0 0 -0 0</pose>
          <geometry>
            <sphere>
              <radius>0.3</radius>
            </sphere>
          </geometry>
          <material>
            <script>
              <uri>__default__</uri>
              <name>__default__</name>
            </script>
          </material>
        </visual>
        <visual name='robot_base_visual_1'>
          <pose frame=''>0 0 0.3 0 -0 0</pose>
          <geometry>
            <sphere>
              <radius>0.1</radius>
            </sphere>
          </geometry>
          <material>
            <script>
              <uri>__default__</uri>
              <name>__default__</name>
            </script>
          </material>
        </visual>
        <visual name='robot_base_visual_2'>
          <pose frame=''>0 0.3 0 0 -0 0</pose>
          <geometry>
            <sphere>
              <radius>0.1</radius>
            </sphere>
          </geometry>
          <material>
            <script>
              <uri>__default__</uri>
              <name>__default__</name>
            </script>
          </material>
        </visual>
        <gravity>1</gravity>
        <velocity_decay/>
        <gravity>1</gravity>
        <sensor name='imu_sensor' type='imu'>
          <always_on>1</always_on>
          <update_rate>100</update_rate>
          <visualize>1</visualize>
          <topic>__default_topic__</topic>
          <plugin name='imu_plugin' filename='libgazebo_ros_imu_sensor.so'>
            <topicName>imu</topicName>
            <bodyName>robot_base</bodyName>
            <updateRateHZ>1000.0</updateRateHZ>
            <gaussianNoise>0.0</gaussianNoise>
            <xyzOffset>0 0 0</xyzOffset>
            <rpyOffset>0 0 0</rpyOffset>
            <frameName>robot_base</frameName>
            <initialOrientationAsReference>0</initialOrientationAsReference>
            <robotNamespace>/</robotNamespace>
          </plugin>
          <pose frame=''>0 0 0 0 -0 0</pose>
          <imu/>
        </sensor>
        <self_collide>0</self_collide>
        <enable_wind>0</enable_wind>
        <kinematic>0</kinematic>
      </link>
      <joint name='robot_joint' type='revolute'>
        <child>robot_base</child>
        <parent>base2_link</parent>
        <axis>
          <xyz>1 0 0</xyz>
          <limit>
            <lower>-1e+16</lower>
            <upper>1e+16</upper>
          </limit>
          <dynamics>
            <spring_reference>0</spring_reference>
            <spring_stiffness>0</spring_stiffness>
          </dynamics>
          <use_parent_model_frame>1</use_parent_model_frame>
        </axis>
      </joint>
      <link name='hip_back'>
        <pose frame=''>0 0 2 0 -0 0</pose>
        <inertial>
          <pose frame=''>0 0 0 0 -0 0</pose>
          <mass>0.3</mass>
          <inertia>
            <ixx>0.05</ixx>
            <ixy>0</ixy>
            <ixz>0</ixz>
            <iyy>0.05</iyy>
            <iyz>0</iyz>
            <izz>0.05</izz>
          </inertia>
        </inertial>
        <collision name='hip_back_collision'>
          <pose frame=''>0 0 0 0 -0 0</pose>
          <geometry>
            <sphere>
              <radius>0.02</radius>
            </sphere>
          </geometry>
          <max_contacts>10</max_contacts>
          <surface>
            <contact>
              <ode/>
            </contact>
            <bounce/>
            <friction>
              <torsional>
                <ode/>
              </torsional>
              <ode/>
            </friction>
          </surface>
        </collision>
        <visual name='hip_back_visual'>
          <pose frame=''>0 0 0 0 -0 0</pose>
          <geometry>
            <sphere>
              <radius>0.02</radius>
            </sphere>
          </geometry>
        </visual>
        <self_collide>0</self_collide>
        <enable_wind>0</enable_wind>
        <kinematic>0</kinematic>
      </link>
      <joint name='hip_back_joint' type='revolute'>
        <child>hip_back</child>
        <parent>robot_base</parent>
        <axis>
          <xyz>0 0 1</xyz>
          <limit>
            <lower>-1e+16</lower>
            <upper>1e+16</upper>
          </limit>
          <dynamics>
            <spring_reference>0</spring_reference>
            <spring_stiffness>0</spring_stiffness>
          </dynamics>
          <use_parent_model_frame>1</use_parent_model_frame>
        </axis>
      </joint>
      <link name='leg_back'>
        <pose frame=''>0 0 2 3.14159 9.3e-05 3.14159</pose>
        <inertial>
          <pose frame=''>0 0 0 0 -0 0</pose>
          <mass>0.3</mass>
          <inertia>
            <ixx>0.05</ixx>
            <ixy>0</ixy>
            <ixz>0</ixz>
            <iyy>0.05</iyy>
            <iyz>0</iyz>
            <izz>0.05</izz>
          </inertia>
        </inertial>
        <collision name='leg_back_collision'>
          <pose frame=''>0 0 0.15 0 -0 0</pose>
          <geometry>
            <cylinder>
              <length>0.3</length>
              <radius>0.02</radius>
            </cylinder>
          </geometry>
          <max_contacts>10</max_contacts>
          <surface>
            <contact>
              <ode/>
            </contact>
            <bounce/>
            <friction>
              <torsional>
                <ode/>
              </torsional>
              <ode/>
            </friction>
          </surface>
        </collision>
        <collision name='leg_back_collision_1'>
          <pose frame=''>0 0 0.3 0 -0 0</pose>
          <geometry>
            <sphere>
              <radius>0.02</radius>
            </sphere>
          </geometry>
          <max_contacts>10</max_contacts>
          <surface>
            <contact>
              <ode/>
            </contact>
            <bounce/>
            <friction>
              <torsional>
                <ode/>
              </torsional>
              <ode/>
            </friction>
          </surface>
        </collision>
        <visual name='leg_back_visual'>
          <pose frame=''>0 0 0.15 0 -0 0</pose>
          <geometry>
            <cylinder>
              <length>0.3</length>
              <radius>0.02</radius>
            </cylinder>
          </geometry>
        </visual>
        <visual name='leg_back_visual_1'>
          <pose frame=''>0 0 0.3 0 -0 0</pose>
          <geometry>
            <sphere>
              <radius>0.02</radius>
            </sphere>
          </geometry>
        </visual>
        <self_collide>0</self_collide>
        <enable_wind>0</enable_wind>
        <kinematic>0</kinematic>
      </link>
      <joint name='leg_back_joint' type='revolute'>
        <child>leg_back</child>
        <parent>hip_back</parent>
        <axis>
          <xyz>1 0 9.3e-05</xyz>
          <limit>
            <lower>-1e+16</lower>
            <upper>1e+16</upper>
          </limit>
          <dynamics>
            <spring_reference>0</spring_reference>
            <spring_stiffness>0</spring_stiffness>
          </dynamics>
          <use_parent_model_frame>1</use_parent_model_frame>
        </axis>
      </joint>
      <link name='foot_back'>
        <pose frame=''>5.6e-05 0 1.4 3.14159 9.3e-05 3.14159</pose>
        <inertial>
          <pose frame=''>0 0 -0.6 0 -0 0</pose>
          <mass>0.3</mass>
          <inertia>
            <ixx>0.05</ixx>
            <ixy>0</ixy>
            <ixz>0</ixz>
            <iyy>0.05</iyy>
            <iyz>0</iyz>
            <izz>0.05</izz>
          </inertia>
        </inertial>
        <collision name='foot_back_collision'>
          <pose frame=''>0 0 0.3 0 -0 0</pose>
          <geometry>
            <cylinder>
              <length>0.6</length>
              <radius>0.02</radius>
            </cylinder>
          </geometry>
          <surface>
            <friction>
              <ode>
                <mu>0.99</mu>
                <mu2>0.99</mu2>
              </ode>
              <torsional>
                <ode/>
              </torsional>
            </friction>
            <contact>
              <ode/>
            </contact>
            <bounce/>
          </surface>
          <max_contacts>10</max_contacts>
        </collision>
        <collision name='foot_back_fixed_joint_lump__foot_bakc_collision_collision_1'>
          <pose frame=''>0 0 0.6 0 -0 0</pose>
          <geometry>
            <sphere>
              <radius>0.02</radius>
            </sphere>
          </geometry>
          <max_contacts>10</max_contacts>
          <surface>
            <contact>
              <ode/>
            </contact>
            <bounce/>
            <friction>
              <torsional>
                <ode/>
              </torsional>
              <ode/>
            </friction>
          </surface>
        </collision>
        <visual name='foot_back_visual'>
          <pose frame=''>0 0 0.3 0 -0 0</pose>
          <geometry>
            <cylinder>
              <length>0.6</length>
              <radius>0.02</radius>
            </cylinder>
          </geometry>
          <material>
            <script>
              <uri>__default__</uri>
              <name>__default__</name>
            </script>
          </material>
        </visual>
        <visual name='foot_back_visual_1'>
          <pose frame=''>0 0 0.6 0 -0 0</pose>
          <geometry>
            <sphere>
              <radius>0.02</radius>
            </sphere>
          </geometry>
          <material>
            <script>
              <uri>__default__</uri>
              <name>__default__</name>
            </script>
          </material>
        </visual>
        <velocity_decay/>
        <sensor name='foot_contact_sensor' type='contact'>
          <contact>
            <collision>foot_back_fixed_joint_lump__foot_bakc_collision_collision_1</collision>
            <topic>__default_topic__</topic>
          </contact>
          <plugin name='foot_back_plugin' filename='libgazebo_ros_bumper.so'>
            <alwaysOn>1</alwaysOn>
            <bumperTopicName>/foot_back_contact</bumperTopicName>
            <frameName>world</frameName>
            <updateRate>100.0</updateRate>
            <robotNamespace>/</robotNamespace>
          </plugin>
        </sensor>
        <gravity>1</gravity>
        <velocity_decay/>
        <self_collide>0</self_collide>
        <enable_wind>0</enable_wind>
        <kinematic>0</kinematic>
      </link>
      <joint name='foot_back_joint' type='prismatic'>
        <child>foot_back</child>
        <parent>leg_back</parent>
        <axis>
          <xyz>9.3e-05 0 -1</xyz>
          <limit>
            <lower>-1</lower>
            <upper>1.2</upper>
            <effort>1000</effort>
            <velocity>4</velocity>
          </limit>
          <dynamics>
            <spring_reference>0</spring_reference>
            <spring_stiffness>0</spring_stiffness>
          </dynamics>
          <use_parent_model_frame>1</use_parent_model_frame>
        </axis>
      </joint>
      <link name='hip_left'>
        <pose frame=''>0 0 2 2.0944 -0 0</pose>
        <inertial>
          <pose frame=''>0 0 0 0 -0 0</pose>
          <mass>0.3</mass>
          <inertia>
            <ixx>0.05</ixx>
            <ixy>0</ixy>
            <ixz>0</ixz>
            <iyy>0.05</iyy>
            <iyz>0</iyz>
            <izz>0.05</izz>
          </inertia>
        </inertial>
        <collision name='hip_left_collision'>
          <pose frame=''>0 0 0 0 -0 0</pose>
          <geometry>
            <sphere>
              <radius>0.02</radius>
            </sphere>
          </geometry>
          <max_contacts>10</max_contacts>
          <surface>
            <contact>
              <ode/>
            </contact>
            <bounce/>
            <friction>
              <torsional>
                <ode/>
              </torsional>
              <ode/>
            </friction>
          </surface>
        </collision>
        <visual name='hip_left_visual'>
          <pose frame=''>0 0 0 0 -0 0</pose>
          <geometry>
            <sphere>
              <radius>0.02</radius>
            </sphere>
          </geometry>
        </visual>
        <self_collide>0</self_collide>
        <enable_wind>0</enable_wind>
        <kinematic>0</kinematic>
      </link>
      <joint name='hip_left_joint' type='revolute'>
        <child>hip_left</child>
        <parent>robot_base</parent>
        <axis>
          <xyz>0 -0.866025 -0.5</xyz>
          <limit>
            <lower>-1e+16</lower>
            <upper>1e+16</upper>
          </limit>
          <dynamics>
            <spring_reference>0</spring_reference>
            <spring_stiffness>0</spring_stiffness>
          </dynamics>
          <use_parent_model_frame>1</use_parent_model_frame>
        </axis>
      </joint>
      <link name='leg_left'>
        <pose frame=''>0 0 2 1.0472 -4.6e-05 3.14151</pose>
        <inertial>
          <pose frame=''>0 0 0 0 -0 0</pose>
          <mass>0.3</mass>
          <inertia>
            <ixx>0.05</ixx>
            <ixy>0</ixy>
            <ixz>0</ixz>
            <iyy>0.05</iyy>
            <iyz>0</iyz>
            <izz>0.05</izz>
          </inertia>
        </inertial>
        <collision name='leg_left_collision'>
          <pose frame=''>0 0 0.15 0 -0 0</pose>
          <geometry>
            <cylinder>
              <length>0.3</length>
              <radius>0.02</radius>
            </cylinder>
          </geometry>
          <max_contacts>10</max_contacts>
          <surface>
            <contact>
              <ode/>
            </contact>
            <bounce/>
            <friction>
              <torsional>
                <ode/>
              </torsional>
              <ode/>
            </friction>
          </surface>
        </collision>
        <collision name='leg_left_collision_1'>
          <pose frame=''>0 0 0.3 0 -0 0</pose>
          <geometry>
            <sphere>
              <radius>0.02</radius>
            </sphere>
          </geometry>
          <max_contacts>10</max_contacts>
          <surface>
            <contact>
              <ode/>
            </contact>
            <bounce/>
            <friction>
              <torsional>
                <ode/>
              </torsional>
              <ode/>
            </friction>
          </surface>
        </collision>
        <visual name='leg_left_visual'>
          <pose frame=''>0 0 0.15 0 -0 0</pose>
          <geometry>
            <cylinder>
              <length>0.3</length>
              <radius>0.02</radius>
            </cylinder>
          </geometry>
        </visual>
        <visual name='leg_left_visual_1'>
          <pose frame=''>0 0 0.3 0 -0 0</pose>
          <geometry>
            <sphere>
              <radius>0.02</radius>
            </sphere>
          </geometry>
        </visual>
        <self_collide>0</self_collide>
        <enable_wind>0</enable_wind>
        <kinematic>0</kinematic>
      </link>
      <joint name='leg_left_joint' type='revolute'>
        <child>leg_left</child>
        <parent>hip_left</parent>
        <axis>
          <xyz>1 -8e-05 -4.6e-05</xyz>
          <limit>
            <lower>-1e+16</lower>
            <upper>1e+16</upper>
          </limit>
          <dynamics>
            <spring_reference>0</spring_reference>
            <spring_stiffness>0</spring_stiffness>
          </dynamics>
          <use_parent_model_frame>1</use_parent_model_frame>
        </axis>
      </joint>
      <link name='foot_left'>
        <pose frame=''>5.6e-05 0.519615 2.3 1.0472 -4.6e-05 3.14151</pose>
        <inertial>
          <pose frame=''>0 0 -0.6 0 -0 0</pose>
          <mass>0.3</mass>
          <inertia>
            <ixx>0.05</ixx>
            <ixy>0</ixy>
            <ixz>0</ixz>
            <iyy>0.05</iyy>
            <iyz>0</iyz>
            <izz>0.05</izz>
          </inertia>
        </inertial>
        <collision name='foot_left_collision'>
          <pose frame=''>0 0 0.3 0 -0 0</pose>
          <geometry>
            <cylinder>
              <length>0.6</length>
              <radius>0.02</radius>
            </cylinder>
          </geometry>
          <surface>
            <friction>
              <ode>
                <mu>0.99</mu>
                <mu2>0.99</mu2>
              </ode>
              <torsional>
                <ode/>
              </torsional>
            </friction>
            <contact>
              <ode/>
            </contact>
            <bounce/>
          </surface>
          <max_contacts>10</max_contacts>
        </collision>
        <collision name='foot_left_collision_collision_1'>
          <pose frame=''>0 0 0.6 0 -0 0</pose>
          <geometry>
            <sphere>
              <radius>0.02</radius>
            </sphere>
          </geometry>
          <surface>
            <friction>
              <ode>
                <mu>0.99</mu>
                <mu2>0.99</mu2>
              </ode>
              <torsional>
                <ode/>
              </torsional>
            </friction>
            <contact>
              <ode/>
            </contact>
            <bounce/>
          </surface>
          <max_contacts>10</max_contacts>
        </collision>
        <visual name='foot_left_visual'>
          <pose frame=''>0 0 0.3 0 -0 0</pose>
          <geometry>
            <cylinder>
              <length>0.6</length>
              <radius>0.02</radius>
            </cylinder>
          </geometry>
          <material>
            <script>
              <uri>__default__</uri>
              <name>__default__</name>
            </script>
          </material>
        </visual>
        <visual name='foot_left_visual_1'>
          <pose frame=''>0 0 0.6 0 -0 0</pose>
          <geometry>
            <sphere>
              <radius>0.02</radius>
            </sphere>
          </geometry>
          <material>
            <script>
              <uri>__default__</uri>
              <name>__default__</name>
            </script>
          </material>
        </visual>
        <velocity_decay/>
        <sensor name='foot_contact_sensor' type='contact'>
          <contact>
            <collision>foot_left_collision_collision_1</collision>
            <topic>__default_topic__</topic>
          </contact>
          <plugin name='foot_left_plugin' filename='libgazebo_ros_bumper.so'>
            <alwaysOn>1</alwaysOn>
            <bumperTopicName>/foot_left_contact</bumperTopicName>
            <frameName>world</frameName>
            <updateRate>100.0</updateRate>
            <robotNamespace>/</robotNamespace>
          </plugin>
        </sensor>
        <gravity>1</gravity>
        <velocity_decay/>
        <self_collide>0</self_collide>
        <enable_wind>0</enable_wind>
        <kinematic>0</kinematic>
      </link>
      <joint name='foot_left_joint' type='prismatic'>
        <child>foot_left</child>
        <parent>leg_left</parent>
        <axis>
          <xyz>9.3e-05 0.866025 0.5</xyz>
          <limit>
            <lower>-1</lower>
            <upper>1.2</upper>
            <effort>1000</effort>
            <velocity>4</velocity>
          </limit>
          <dynamics>
            <spring_reference>0</spring_reference>
            <spring_stiffness>0</spring_stiffness>
          </dynamics>
          <use_parent_model_frame>1</use_parent_model_frame>
        </axis>
      </joint>
      <link name='hip_right'>
        <pose frame=''>0 0 2 -2.0944 -0 0</pose>
        <inertial>
          <pose frame=''>0 0 0 0 -0 0</pose>
          <mass>0.3</mass>
          <inertia>
            <ixx>0.05</ixx>
            <ixy>0</ixy>
            <ixz>0</ixz>
            <iyy>0.05</iyy>
            <iyz>0</iyz>
            <izz>0.05</izz>
          </inertia>
        </inertial>
        <collision name='hip_right_collision'>
          <pose frame=''>0 0 0 0 -0 0</pose>
          <geometry>
            <sphere>
              <radius>0.02</radius>
            </sphere>
          </geometry>
          <max_contacts>10</max_contacts>
          <surface>
            <contact>
              <ode/>
            </contact>
            <bounce/>
            <friction>
              <torsional>
                <ode/>
              </torsional>
              <ode/>
            </friction>
          </surface>
        </collision>
        <visual name='hip_right_visual'>
          <pose frame=''>0 0 0 0 -0 0</pose>
          <geometry>
            <sphere>
              <radius>0.02</radius>
            </sphere>
          </geometry>
        </visual>
        <self_collide>0</self_collide>
        <enable_wind>0</enable_wind>
        <kinematic>0</kinematic>
      </link>
      <joint name='hip_right_joint' type='revolute'>
        <child>hip_right</child>
        <parent>robot_base</parent>
        <axis>
          <xyz>0 0.866025 -0.5</xyz>
          <limit>
            <lower>-1e+16</lower>
            <upper>1e+16</upper>
          </limit>
          <dynamics>
            <spring_reference>0</spring_reference>
            <spring_stiffness>0</spring_stiffness>
          </dynamics>
          <use_parent_model_frame>1</use_parent_model_frame>
        </axis>
      </joint>
      <link name='leg_right'>
        <pose frame=''>0 0 2 -1.0472 -4.6e-05 -3.14151</pose>
        <inertial>
          <pose frame=''>0 0 0 0 -0 0</pose>
          <mass>0.3</mass>
          <inertia>
            <ixx>0.05</ixx>
            <ixy>0</ixy>
            <ixz>0</ixz>
            <iyy>0.05</iyy>
            <iyz>0</iyz>
            <izz>0.05</izz>
          </inertia>
        </inertial>
        <collision name='leg_right_collision'>
          <pose frame=''>0 0 0.15 0 -0 0</pose>
          <geometry>
            <cylinder>
              <length>0.3</length>
              <radius>0.02</radius>
            </cylinder>
          </geometry>
          <max_contacts>10</max_contacts>
          <surface>
            <contact>
              <ode/>
            </contact>
            <bounce/>
            <friction>
              <torsional>
                <ode/>
              </torsional>
              <ode/>
            </friction>
          </surface>
        </collision>
        <collision name='leg_right_collision_1'>
          <pose frame=''>0 0 0.3 0 -0 0</pose>
          <geometry>
            <sphere>
              <radius>0.02</radius>
            </sphere>
          </geometry>
          <max_contacts>10</max_contacts>
          <surface>
            <contact>
              <ode/>
            </contact>
            <bounce/>
            <friction>
              <torsional>
                <ode/>
              </torsional>
              <ode/>
            </friction>
          </surface>
        </collision>
        <visual name='leg_right_visual'>
          <pose frame=''>0 0 0.15 0 -0 0</pose>
          <geometry>
            <cylinder>
              <length>0.3</length>
              <radius>0.02</radius>
            </cylinder>
          </geometry>
        </visual>
        <visual name='leg_right_visual_1'>
          <pose frame=''>0 0 0.3 0 -0 0</pose>
          <geometry>
            <sphere>
              <radius>0.02</radius>
            </sphere>
          </geometry>
        </visual>
        <self_collide>0</self_collide>
        <enable_wind>0</enable_wind>
        <kinematic>0</kinematic>
      </link>
      <joint name='leg_right_joint' type='revolute'>
        <child>leg_right</child>
        <parent>hip_right</parent>
        <axis>
          <xyz>1 8e-05 -4.6e-05</xyz>
          <limit>
            <lower>-1e+16</lower>
            <upper>1e+16</upper>
          </limit>
          <dynamics>
            <spring_reference>0</spring_reference>
            <spring_stiffness>0</spring_stiffness>
          </dynamics>
          <use_parent_model_frame>1</use_parent_model_frame>
        </axis>
      </joint>
      <link name='foot_right'>
        <pose frame=''>5.6e-05 -0.519615 2.3 -1.0472 -4.6e-05 -3.14151</pose>
        <inertial>
          <pose frame=''>0 0 -0.6 0 -0 0</pose>
          <mass>0.3</mass>
          <inertia>
            <ixx>0.05</ixx>
            <ixy>0</ixy>
            <ixz>0</ixz>
            <iyy>0.05</iyy>
            <iyz>0</iyz>
            <izz>0.05</izz>
          </inertia>
        </inertial>
        <collision name='foot_right_collision'>
          <pose frame=''>0 0 0.3 0 -0 0</pose>
          <geometry>
            <cylinder>
              <length>0.6</length>
              <radius>0.02</radius>
            </cylinder>
          </geometry>
          <surface>
            <friction>
              <ode>
                <mu>0.99</mu>
                <mu2>0.99</mu2>
              </ode>
              <torsional>
                <ode/>
              </torsional>
            </friction>
            <contact>
              <ode/>
            </contact>
            <bounce/>
          </surface>
          <max_contacts>10</max_contacts>
        </collision>
        <collision name='foot_right_collision_collision_1'>
          <pose frame=''>0 0 0.6 0 -0 0</pose>
          <geometry>
            <sphere>
              <radius>0.02</radius>
            </sphere>
          </geometry>
          <surface>
            <friction>
              <ode>
                <mu>0.99</mu>
                <mu2>0.99</mu2>
              </ode>
              <torsional>
                <ode/>
              </torsional>
            </friction>
            <contact>
              <ode/>
            </contact>
            <bounce/>
          </surface>
          <max_contacts>10</max_contacts>
        </collision>
        <visual name='foot_right_visual'>
          <pose frame=''>0 0 0.3 0 -0 0</pose>
          <geometry>
            <cylinder>
              <length>0.6</length>
              <radius>0.02</radius>
            </cylinder>
          </geometry>
          <material>
            <script>
              <uri>__default__</uri>
              <name>__default__</name>
            </script>
          </material>
        </visual>
        <visual name='foot_right_visual_1'>
          <pose frame=''>0 0 0.6 0 -0 0</pose>
          <geometry>
            <sphere>
              <radius>0.02</radius>
            </sphere>
          </geometry>
          <material>
            <script>
              <uri>__default__</uri>
              <name>__default__</name>
            </script>
          </material>
        </visual>
        <velocity_decay/>
        <sensor name='foot_contact_sensor' type='contact'>
          <contact>
            <collision>foot_right_collision_collision_1</collision>
            <topic>__default_topic__</topic>
          </contact>
          <plugin name='foot_right_plugin' filename='libgazebo_ros_bumper.so'>
            <alwaysOn>1</alwaysOn>
            <bumperTopicName>/foot_right_contact</bumperTopicName>
            <frameName>world</frameName>
            <updateRate>100.0</updateRate>
            <robotNamespace>/</robotNamespace>
          </plugin>
        </sensor>
        <gravity>1</gravity>
        <velocity_decay/>
        <self_collide>0</self_collide>
        <enable_wind>0</enable_wind>
        <kinematic>0</kinematic>
      </link>
      <joint name='foot_right_joint' type='prismatic'>
        <child>foot_right</child>
        <parent>leg_right</parent>
        <axis>
          <xyz>9.3e-05 -0.866025 0.5</xyz>
          <limit>
            <lower>-1</lower>
            <upper>1.2</upper>
            <effort>1000</effort>
            <velocity>4</velocity>
          </limit>
          <dynamics>
            <spring_reference>0</spring_reference>
            <spring_stiffness>0</spring_stiffness>
          </dynamics>
          <use_parent_model_frame>1</use_parent_model_frame>
        </axis>
      </joint>
      <static>0</static>
      <plugin name='gazebo_ros_control' filename='libgazebo_ros_control.so'>
        <robotNamespace>/singlebot</robotNamespace>
      </plugin>
      <pose frame=''>0 0 0 0 -0 0</pose>
    </model>
    <state world_name='default'>
      <sim_time>0 500000000</sim_time>
      <real_time>0 0</real_time>
      <wall_time>1623796552 871291772</wall_time>
      <iterations>500</iterations>
      <model name='ground_plane'>
        <pose frame=''>0 0 0 0 -0 0</pose>
        <scale>1 1 1</scale>
        <link name='link'>
          <pose frame=''>0 0 0 0 -0 0</pose>
          <velocity>0 0 0 0 -0 0</velocity>
          <acceleration>0 0 0 0 -0 0</acceleration>
          <wrench>0 0 0 0 -0 0</wrench>
        </link>
      </model>
      <model name='singlebot'>
        <pose frame=''>-0 -0 -0.81172 -0 -0 -0</pose>
        <scale>1 1 1</scale>
        <link name='base1_link'>
          <pose frame=''>-0 -0 -0.81172 -0 -0 -0</pose>
          <velocity>-6e-06 -0 -0.922918 0 -2e-06 0</velocity>
          <acceleration>-0.015286 -0 13.4985 0 -0.005321 -7e-06</acceleration>
          <wrench>-0.000153 -0 0.134985 0 -0 0</wrench>
        </link>
        <link name='base2_link'>
          <pose frame=''>0 0.005759 1.18828 0 -0 0</pose>
          <velocity>-1e-06 0.058971 -0.922918 0 -1.1e-05 0</velocity>
          <acceleration>0.001435 0.268083 13.4985 -0 -0.029069 0.000131</acceleration>
          <wrench>0.000143 0.026808 1.34985 0 -0 0</wrench>
        </link>
        <link name='foot_back'>
          <pose frame=''>5.4e-05 -0.007761 0.61983 -3.11782 9.3e-05 -3.14156</pose>
          <velocity>-4.2e-05 0.042261 0.009033 -0.068181 -6.7e-05 -8.7e-05</velocity>
          <acceleration>-0.017454 10.6488 438.337 -2.12084 -0.169644 0.006215</acceleration>
          <wrench>-0.005236 3.19463 131.501 0 -0 0</wrench>
        </link>
        <link name='foot_left'>
          <pose frame=''>5.5e-05 0.512883 1.47944 1.0496 -4.5e-05 3.14151</pose>
          <velocity>-6e-06 0.054025 -0.969817 -0.065338 -1.4e-05 -0</velocity>
          <acceleration>0.006256 1.05552 13.968 -0.738051 -0.008903 0.015307</acceleration>
          <wrench>0.001877 0.316656 4.1904 0 -0 0</wrench>
        </link>
        <link name='foot_right'>
          <pose frame=''>5.5e-05 -0.499956 1.48342 -1.04252 -4.6e-05 -3.14151</pose>
          <velocity>-6e-06 0.105976 -0.895534 -0.080851 -1e-05 -1e-06</velocity>
          <acceleration>0.005964 -0.261681 13.7913 -0.652497 -0.008717 -0.014629</acceleration>
          <wrench>0.001789 -0.078504 4.13738 0 -0 0</wrench>
        </link>
        <link name='hip_back'>
          <pose frame=''>0 0.005759 1.18828 -0.00442 -0 3.1e-05</pose>
          <velocity>2e-06 0.058971 -0.922918 -0.079199 -2.4e-05 -8.9e-05</velocity>
          <acceleration>0.009832 0.269257 13.4984 -0.696065 -0.062719 0.004373</acceleration>
          <wrench>0.002949 0.080777 4.04953 0 -0 0</wrench>
        </link>
        <link name='hip_left'>
          <pose frame=''>0 0.005759 1.18828 2.08998 -1e-06 0</pose>
          <velocity>0 0.058971 -0.922918 -0.079199 -1.2e-05 0</velocity>
          <acceleration>0.005849 0.267793 13.4985 -0.696066 -0.008847 0.015201</acceleration>
          <wrench>0.001755 0.080338 4.04956 0 -0 0</wrench>
        </link>
        <link name='hip_right'>
          <pose frame=''>0 0.005759 1.18828 -2.09882 -1e-06 0</pose>
          <velocity>0 0.058971 -0.922918 -0.079199 -1e-05 -2e-06</velocity>
          <acceleration>0.006181 0.268003 13.4985 -0.696066 -0.00931 -0.015638</acceleration>
          <wrench>0.001854 0.080401 4.04954 0 -0 0</wrench>
        </link>
        <link name='leg_back'>
          <pose frame=''>0 0.005759 1.18828 -3.11782 9.3e-05 -3.14156</pose>
          <velocity>3e-06 0.058972 -0.922918 -0.068188 -3.1e-05 -8.8e-05</velocity>
          <acceleration>0.012358 0.269932 13.4984 -2.14196 -0.080991 0.004056</acceleration>
          <wrench>0.003707 0.08098 4.04952 0 -0 0</wrench>
        </link>
        <link name='leg_left'>
          <pose frame=''>0 0.005759 1.18828 1.0496 -4.5e-05 3.14151</pose>
          <velocity>0 0.058971 -0.922918 -0.065338 -1.4e-05 -0</velocity>
          <acceleration>0.005836 0.267837 13.4986 -0.738051 -0.00883 0.015178</acceleration>
          <wrench>0.001751 0.080351 4.04957 0 -0 0</wrench>
        </link>
        <link name='leg_right'>
          <pose frame=''>0 0.005759 1.18828 -1.04252 -4.6e-05 -3.14151</pose>
          <velocity>0 0.058971 -0.922918 -0.080851 -1e-05 -2e-06</velocity>
          <acceleration>0.005887 0.267781 13.4984 -0.652497 -0.008975 -0.015071</acceleration>
          <wrench>0.001766 0.080334 4.04953 0 -0 0</wrench>
        </link>
        <link name='robot_base'>
          <pose frame=''>0 0.005759 1.18828 -0.00442 -0 0</pose>
          <velocity>0 0.058971 -0.922918 -0.079199 -1.4e-05 0</velocity>
          <acceleration>0.00625 0.268059 13.4985 -0.696066 -0.036638 0.000161</acceleration>
          <wrench>0.01875 0.804178 40.4954 0 -0 0</wrench>
        </link>
      </model>
      <light name='sun'>
        <pose frame=''>0 0 10 0 -0 0</pose>
      </light>
    </state>
    <gui fullscreen='0'>
      <camera name='user_camera'>
        <pose frame=''>9.70493 -4.91532 2.98427 -0 0.263643 2.65219</pose>
        <view_controller>orbit</view_controller>
        <projection_type>perspective</projection_type>
      </camera>
    </gui>
  </world>
</sdf>
