<?xml version="1.0" ?>
<!-- =================================================================================== -->
<!-- |    This document was autogenerated by xacro from /home/rocky/tribot_ws/src/tribot/urdf/world.xacro | -->
<!-- |    EDITING THIS FILE BY HAND IS NOT RECOMMENDED                                 | -->
<!-- =================================================================================== -->
<robot name="world">
    <link name="world" />
    <link name="base_link">
        
<inertial>
            <origin rpy="0 0 0" xyz="0 0 0" />
            <mass value="2" />
            <inertia ixx="0.1" ixy="0" ixz="0" iyy="0.1" iyz="0" izz="0.1" />
        </inertial>

        <visual>
            <origin rpy="0 0 0" xyz="0 0 0" />
            <geometry>
                <cylinder length="0.2" radius="0.3" />
            </geometry>
            <material name="framemat0">
                <color rgba="1 1 1 1" />
            </material>
        </visual>
        <collision>
            <origin rpy="0 0 0" xyz="0 0 0" />
            <geometry>
                <cylinder length="0.2" radius="0.3" />
            </geometry>
        </collision>
    </link>
    <link name="hip_back">
        
<inertial>
            <origin rpy="0 0 0" xyz="0 0 0" />
            <mass value="0.3" />
            <inertia ixx="0.1" ixy="0" ixz="0" iyy="0.1" iyz="0" izz="0.1" />
        </inertial>

        <visual>
            <origin rpy="0 0 0" xyz="0 0 0" />
            <geometry>
                <sphere radius="0.05" />
            </geometry>
            <material name="framemat0">
                <color rgba="1 1 1 1" />
            </material>
        </visual>
        <collision>
            <origin rpy="0 0 0" xyz="0 0 0" />
            <geometry>
                <sphere radius="0.05" />
            </geometry>
        </collision>
    </link>
    <link name="hip_left">
        
<inertial>
            <origin rpy="0 0 0" xyz="0 0 0" />
            <mass value="0.3" />
            <inertia ixx="0.1" ixy="0" ixz="0" iyy="0.1" iyz="0" izz="0.1" />
        </inertial>

        <visual>
            <origin rpy="0 0 0" xyz="0 0 0" />
            <geometry>
                <sphere radius="0.05" />
            </geometry>
            <material name="framemat0">
                <color rgba="1 1 1 1" />
            </material>
        </visual>
        <collision>
            <origin rpy="0 0 0" xyz="0 0 0" />
            <geometry>
                <sphere radius="0.05" />
            </geometry>
        </collision>
    </link>
    <link name="hip_right">
        
<inertial>
            <origin rpy="0 0 0" xyz="0 0 0" />
            <mass value="0.3" />
            <inertia ixx="0.1" ixy="0" ixz="0" iyy="0.1" iyz="0" izz="0.1" />
        </inertial>

        <visual>
            <origin rpy="0 0 0" xyz="0 0 0" />
            <geometry>
                <sphere radius="0.05" />
            </geometry>
            <material name="framemat0">
                <color rgba="1 1 1 1" />
            </material>
        </visual>
        <collision>
            <origin rpy="0 0 0" xyz="0 0 0" />
            <geometry>
                <sphere radius="0.05" />
            </geometry>
        </collision>
    </link>
    <link name="leg_back">
        
<inertial>
            <origin rpy="0 0 0" xyz="0 0 0.15" />
            <mass value="0.3" />
            <inertia ixx="0.1" ixy="0" ixz="0" iyy="0.1" iyz="0" izz="0.1" />
        </inertial>

        <visual>
            <origin rpy="0 0 0" xyz="0 0 0.15" />
            <geometry>
                <cylinder length="0.3" radius="0.05" />
            </geometry>
            <material name="framemat0">
                <color rgba="1 1 1 1" />
            </material>
        </visual>
        <collision>
            <origin rpy="0 0 0" xyz="0 0 0.15" />
            <geometry>
                <cylinder length="0.3" radius="0.05" />
            </geometry>
        </collision>
        <visual>
            <origin rpy="0 0 0" xyz="0 0 0.3" />
            <geometry>
                <sphere radius="0.05" />
            </geometry>
            <material name="framemat0">
                <color rgba="1 1 1 1" />
            </material>
        </visual>
        <collision>
            <origin rpy="0 0 0" xyz="0 0 0.3" />
            <geometry>
                <sphere radius="0.05" />
            </geometry>
        </collision>
    </link>
    <link name="leg_left">
        
<inertial>
            <origin rpy="0 0 0" xyz="0 0 0.15" />
            <mass value="0.3" />
            <inertia ixx="0.1" ixy="0" ixz="0" iyy="0.1" iyz="0" izz="0.1" />
        </inertial>

        <visual>
            <origin rpy="0 0 0" xyz="0 0 0.15" />
            <geometry>
                <cylinder length="0.3" radius="0.05" />
            </geometry>
            <material name="framemat0">
                <color rgba="1 1 1 1" />
            </material>
        </visual>
        <collision>
            <origin rpy="0 0 0" xyz="0 0 0.15" />
            <geometry>
                <cylinder length="0.3" radius="0.05" />
            </geometry>
        </collision>
        <visual>
            <origin rpy="0 0 0" xyz="0 0 0.3" />
            <geometry>
                <sphere radius="0.05" />
            </geometry>
            <material name="framemat0">
                <color rgba="1 1 1 1" />
            </material>
        </visual>
        <collision>
            <origin rpy="0 0 0" xyz="0 0 0.3" />
            <geometry>
                <sphere radius="0.05" />
            </geometry>
        </collision>
    </link>
    <link name="leg_right">
        
<inertial>
            <origin rpy="0 0 0" xyz="0 0 0.15" />
            <mass value="0.3" />
            <inertia ixx="0.1" ixy="0" ixz="0" iyy="0.1" iyz="0" izz="0.1" />
        </inertial>

        <visual>
            <origin rpy="0 0 0" xyz="0 0 0.15" />
            <geometry>
                <cylinder length="0.3" radius="0.05" />
            </geometry>
            <material name="framemat0">
                <color rgba="1 1 1 1" />
            </material>
        </visual>
        <collision>
            <origin rpy="0 0 0" xyz="0 0 0.15" />
            <geometry>
                <cylinder length="0.3" radius="0.05" />
            </geometry>
        </collision>
        <visual>
            <origin rpy="0 0 0" xyz="0 0 0.3" />
            <geometry>
                <sphere radius="0.05" />
            </geometry>
            <material name="framemat0">
                <color rgba="1 1 1 1" />
            </material>
        </visual>
        <collision>
            <origin rpy="0 0 0" xyz="0 0 0.3" />
            <geometry>
                <sphere radius="0.05" />
            </geometry>
        </collision>
    </link>
    <link name="foot_back">
        
<inertial>
            <origin rpy="0 0 0" xyz="0 0 0.15" />
            <mass value="0.3" />
            <inertia ixx="0.1" ixy="0" ixz="0" iyy="0.1" iyz="0" izz="0.1" />
        </inertial>

        <visual>
            <origin rpy="0 0 0" xyz="0 0 0.15" />
            <geometry>
                <cylinder length="0.3" radius="0.05" />
            </geometry>
            <material name="framemat0">
                <color rgba="1 1 1 1" />
            </material>
        </visual>
        <collision>
            <origin rpy="0 0 0" xyz="0 0 0.15" />
            <geometry>
                <cylinder length="0.3" radius="0.05" />
            </geometry>
        </collision>
        <visual>
            <origin rpy="0 0 0" xyz="0 0 0.3" />
            <geometry>
                <sphere radius="0.05" />
            </geometry>
            <material name="framemat0">
                <color rgba="1 1 1 1" />
            </material>
        </visual>
        <collision>
            <origin rpy="0 0 0" xyz="0 0 0.3" />
            <geometry>
                <sphere radius="0.05" />
            </geometry>
        </collision>
    </link>
    <link name="foot_left">
        
<inertial>
            <origin rpy="0 0 0" xyz="0 0 0.15" />
            <mass value="0.3" />
            <inertia ixx="0.1" ixy="0" ixz="0" iyy="0.1" iyz="0" izz="0.1" />
        </inertial>

        <visual>
            <origin rpy="0 0 0" xyz="0 0 0.15" />
            <geometry>
                <cylinder length="0.3" radius="0.05" />
            </geometry>
            <material name="framemat0">
                <color rgba="1 1 1 1" />
            </material>
        </visual>
        <collision>
            <origin rpy="0 0 0" xyz="0 0 0.15" />
            <geometry>
                <cylinder length="0.3" radius="0.05" />
            </geometry>
        </collision>
        <visual>
            <origin rpy="0 0 0" xyz="0 0 0.3" />
            <geometry>
                <sphere radius="0.05" />
            </geometry>
            <material name="framemat0">
                <color rgba="1 1 1 1" />
            </material>
        </visual>
        <collision>
            <origin rpy="0 0 0" xyz="0 0 0.3" />
            <geometry>
                <sphere radius="0.05" />
            </geometry>
        </collision>
    </link>
    <link name="foot_right">
        
<inertial>
            <origin rpy="0 0 0" xyz="0 0 0.15" />
            <mass value="0.3" />
            <inertia ixx="0.1" ixy="0" ixz="0" iyy="0.1" iyz="0" izz="0.1" />
        </inertial>

        <visual>
            <origin rpy="0 0 0" xyz="0 0 0.15" />
            <geometry>
                <cylinder length="0.3" radius="0.05" />
            </geometry>
            <material name="framemat0">
                <color rgba="1 1 1 1" />
            </material>
        </visual>
        <collision>
            <origin rpy="0 0 0" xyz="0 0 0.15" />
            <geometry>
                <cylinder length="0.3" radius="0.05" />
            </geometry>
        </collision>
        <visual>
            <origin rpy="0 0 0" xyz="0 0 0.3" />
            <geometry>
                <sphere radius="0.05" />
            </geometry>
            <material name="framemat0">
                <color rgba="1 1 1 1" />
            </material>
        </visual>
        <collision>
            <origin rpy="0 0 0" xyz="0 0 0.3" />
            <geometry>
                <sphere radius="0.05" />
            </geometry>
        </collision>
    </link>
    <joint name="hip_back_joint" type="continuous">
        <parent link="base_link" />
        <child link="hip_back" />
        <origin rpy="0 0 3.1415" xyz="-0.3 0 0" />
        <axis xyz="1 0 0" />
    </joint>
    <joint name="hip_left_joint" type="continuous">
        <parent link="base_link" />
        <child link="hip_left" />
        <origin rpy="0 0 1.0472" xyz="0.15 0.2598  0" />
        <axis xyz="1 0 0" />
    </joint>
    <joint name="hip_right_joint" type="continuous">
        <parent link="base_link" />
        <child link="hip_right" />
        <origin rpy="0 0 -1.0472" xyz="0.15 -0.2598  0" />
        <axis xyz="1 0 0" />
    </joint>
    <joint name="leg_back_joint" type="continuous">
        <parent link="hip_back" />
        <child link="leg_back" />
        <origin rpy="0 1.57 0" xyz="0 0 0" />
        <axis xyz="0 1 0" />
    </joint>
    <joint name="leg_left_joint" type="continuous">
        <parent link="hip_left" />
        <child link="leg_left" />
        <origin rpy="0 1.57 0" xyz="0 0 0" />
        <axis xyz="0 1 0" />
    </joint>
    <joint name="leg_right_joint" type="continuous">
        <parent link="hip_right" />
        <child link="leg_right" />
        <origin rpy="0 1.57 0" xyz="0 0 0" />
        <axis xyz="0 1 0" />
    </joint>
    <joint name="foot_back_joint" type="continuous">
        <parent link="leg_back" />
        <child link="foot_back" />
        <origin rpy="0 0 0" xyz="0 0 0.3" />
        <axis xyz="0 1 0" />
    </joint>
    <joint name="foot_left_joint" type="continuous">
        <parent link="leg_left" />
        <child link="foot_left" />
        <origin rpy="0 0 0" xyz="0 0 0.3" />
        <axis xyz="0 1 0" />
    </joint>
    <joint name="foot_right_joint" type="continuous">
        <parent link="leg_right" />
        <child link="foot_right" />
        <origin rpy="0 0 0" xyz="0 0 0.3" />
        <axis xyz="0 1 0" />
    </joint>
    <joint name="base_joint" type="fixed">
        <parent link="world" />
        <child link="base_link" />
        <origin rpy="0 0 0" xyz="0 0 0" />
        <axis xyz="1 0 0" />
    </joint>
    
<transmission name="trans_hip_back_joint">
        <type>transmission_interface/SimpleTransmission</type>
        <joint name="hip_back_joint">
            <hardwareInterface>hardware_interface/EffortJointInterface</hardwareInterface>
        </joint>
        <actuator name="hip_back_joint_motor">
            <hardwareInterface>hardware_interface/EffortJointInterface</hardwareInterface>
            <mechanicalReduction>1</mechanicalReduction>
        </actuator>
    </transmission>
    <transmission name="trans_hip_left_joint">
        <type>transmission_interface/SimpleTransmission</type>
        <joint name="hip_left_joint">
            <hardwareInterface>hardware_interface/EffortJointInterface</hardwareInterface>
        </joint>
        <actuator name="hip_left_joint_motor">
            <hardwareInterface>hardware_interface/EffortJointInterface</hardwareInterface>
            <mechanicalReduction>1</mechanicalReduction>
        </actuator>
    </transmission>
    <transmission name="trans_hip_right_joint">
        <type>transmission_interface/SimpleTransmission</type>
        <joint name="hip_right_joint">
            <hardwareInterface>hardware_interface/EffortJointInterface</hardwareInterface>
        </joint>
        <actuator name="hip_right_joint_motor">
            <hardwareInterface>hardware_interface/EffortJointInterface</hardwareInterface>
            <mechanicalReduction>1</mechanicalReduction>
        </actuator>
    </transmission>
    <transmission name="trans_leg_back_joint">
        <type>transmission_interface/SimpleTransmission</type>
        <joint name="leg_back_joint">
            <hardwareInterface>hardware_interface/EffortJointInterface</hardwareInterface>
        </joint>
        <actuator name="leg_back_joint_motor">
            <hardwareInterface>hardware_interface/EffortJointInterface</hardwareInterface>
            <mechanicalReduction>1</mechanicalReduction>
        </actuator>
    </transmission>
    <transmission name="trans_leg_left_joint">
        <type>transmission_interface/SimpleTransmission</type>
        <joint name="leg_left_joint">
            <hardwareInterface>hardware_interface/EffortJointInterface</hardwareInterface>
        </joint>
        <actuator name="leg_left_joint_motor">
            <hardwareInterface>hardware_interface/EffortJointInterface</hardwareInterface>
            <mechanicalReduction>1</mechanicalReduction>
        </actuator>
    </transmission>
    <transmission name="trans_leg_right_joint">
        <type>transmission_interface/SimpleTransmission</type>
        <joint name="leg_right_joint">
            <hardwareInterface>hardware_interface/EffortJointInterface</hardwareInterface>
        </joint>
        <actuator name="leg_right_joint_motor">
            <hardwareInterface>hardware_interface/EffortJointInterface</hardwareInterface>
            <mechanicalReduction>1</mechanicalReduction>
        </actuator>
    </transmission>
    <transmission name="trans_foot_back_joint">
        <type>transmission_interface/SimpleTransmission</type>
        <joint name="foot_back_joint">
            <hardwareInterface>hardware_interface/EffortJointInterface</hardwareInterface>
        </joint>
        <actuator name="foot_back_joint_motor">
            <hardwareInterface>hardware_interface/EffortJointInterface</hardwareInterface>
            <mechanicalReduction>1</mechanicalReduction>
        </actuator>
    </transmission>
    <transmission name="trans_foot_left_joint">
        <type>transmission_interface/SimpleTransmission</type>
        <joint name="foot_left_joint">
            <hardwareInterface>hardware_interface/EffortJointInterface</hardwareInterface>
        </joint>
        <actuator name="foot_left_joint_motor">
            <hardwareInterface>hardware_interface/EffortJointInterface</hardwareInterface>
            <mechanicalReduction>1</mechanicalReduction>
        </actuator>
    </transmission>
    <transmission name="trans_foot_right_joint">
        <type>transmission_interface/SimpleTransmission</type>
        <joint name="foot_right_joint">
            <hardwareInterface>hardware_interface/EffortJointInterface</hardwareInterface>
        </joint>
        <actuator name="foot_right_joint_motor">
            <hardwareInterface>hardware_interface/EffortJointInterface</hardwareInterface>
            <mechanicalReduction>1</mechanicalReduction>
        </actuator>
    </transmission>
    <gazebo>
        <plugin name="gazebo_ros_control" filename="libgazebo_ros_control.so">
            <robotNamespace>/</robotNamespace>
        </plugin>
    </gazebo>
</robot>